Workbook
Name ALL2ALL_CORE2CORE_TIME_MS: LAMBDA(global_data_traffic_in_mib, global_data_traffic_in_mib * 1024^2 /(2 * HW_SPEC("Core-to-Core ICI Bandwidth (uni, GB/s)") *1024^3)*1000)
Name ALL2ALL_CHIP2CHIP_TIME_MS: LAMBDA(data_size_in_mib, bisection_links, data_size_in_mib * 1024^2 /4 / (bisection_links * HW_SPEC("Chip-to-Chip ICI Bandwidth (uni, GB/s)") *1000^3) *1000)
Name EXTRACT_ACTIVATION_DTYPE: LAMBDA(wxay, LET(bits, REGEXEXTRACT(wXaY, "a(\d+)"), SWITCH(bits, "4", "fp4", "8", "fp8", "16", "bf16", bits)))
Name REDUCE_SCATTER_CHIP2CHIP_TIME_MS: LAMBDA(global_data_traffic_size_in_mib, global_data_traffic_size_in_mib * 1024^2 / PARAMS("num_links_in_topo") / (2 * HW_SPEC("Chip-to-Chip ICI Bandwidth (uni, GB/s)") * 1024^3) * 1000)
Name REDUCE_SCATTER_CORE2CORE_TIME_MS: LAMBDA(global_data_traffic_in_mib, IF(global_data_traffic_in_mib=0, 0, global_data_traffic_in_mib * 1024^2 /(2 * HW_SPEC("Core-to-Core ICI Bandwidth (uni, GB/s)") *1024^3)*1000 ))
Name ALL_REDUCE_CORE2CORE_TIME_MS: LAMBDA(data_size_in_mib, 2 * data_size_in_mib * 1024^2 / ( 2 * HW_SPEC("Core-to-Core ICI Bandwidth (uni, GB/s)") *1024^3)*1000)
Name EXTRACT_WEIGHT_DTYPE: LAMBDA(wxay, LET(bits, REGEXEXTRACT(wXaY, "w(\d+)"), SWITCH(bits, "4", "fp4", "8", "fp8", "16", "bf16", bits)))
Name ALL2ALL_CHIP2CHIP_TIME_MS2: LAMBDA(data_size_in_mib, num_links, data_size_in_mib * 1024^2 /num_links / (2* HW_SPEC("Chip-to-Chip ICI Bandwidth (uni, GB/s)") *1024^3) *1000)
Name ALL_GATHER_CHIP2CHIP_TIME_MS: LAMBDA(global_data_traffic_size_in_mib, global_data_traffic_size_in_mib / PARAMS("num_links_in_topo") * 1024^2 /(2* HW_SPEC("Chip-to-Chip ICI Bandwidth (uni, GB/s)") *1024^3)*1000)
Name PAD_128: LAMBDA(val, CEILING(val, 128))
Name HBM_TIME_MS: LAMBDA(tensor_size_in_mib, tensor_size_in_mib * 1024^2 / ( VLOOKUP("Per-Core HBM-BW (GB/s)", INDIRECT("$F$16:$H$29"), 3, False) * 1024^3) * 1000)
Name PARAMS: LAMBDA(param_name, IF(ISNUMBER(param_name), param_name, vlookup(param_name,INDIRECT("$B$2:$C$43") ,2,FALSE) ))
Name ALL_GATHER_CORE2CORE_TIME_MS: LAMBDA(global_data_traffic_in_mib, global_data_traffic_in_mib * 1024^2 /(2 * HW_SPEC("Core-to-Core ICI Bandwidth (uni, GB/s)") *1024^3)*1000)
Name HW_SPEC: LAMBDA(spec_name, VLOOKUP(spec_name,INDIRECT("$F$16:$H$31"),3, False))
Name SHARDING: LAMBDA(param_name, IF(ISBLANK(param_name),1, vlookup(param_name, INDIRECT("$F$2:$G$10"),2,FALSE) ))
Name SIZEOF_IN_MIB: LAMBDA(param_name, dtype, PRODUCT( param_name) * vlookup(dtype,INDIRECT("$Q$2:$R$49") ,2,FALSE) / 1024^2)
Name COMPUTE_TIME_MS: LAMBDA(flops, mxu_dtype, flops / (VLOOKUP("Per-Core TFLOPS (" & mxu_dtype & ")",INDIRECT("$F$17:$H$43"),3,FALSE) * 1000000000000) * 1000)

Sheet Model info & Targets
A1: https://huggingface.co/mistralai/Mistral-Large-3-675B-Instruct-2512/blob/main/params.json
B7: GB200 Target (2k/.5k)
B8: Concurrency | C8: Request Throughput (req/min) | D8: Output tok/s | E8: Total tok/s | F8: Output tok/s/chip | G8: Total tok/s/chip | H8: Mean TPOT (ms) | I8: Mean ITL (ms | J8: Gen Time (s) (500 tokens)
B9: 1 | C9: 17 | D9: 131.1 | E9: 703 | F9: 16.4 | G9: 87.9 | H9: 7.45 | I9: 7.45 | J9: =H9*500/1000 -> 3.725
B10: 2 | C10: 28 | D10: 231.2 | E10: 1249 | F10: 28.9 | G10: 156.1 | H10: 8.38 | I10: 8.38 | J10: =H10*500/1000 -> 4.19
B11: 4 | C11: 50 | D11: 426.1 | E11: 2261.6 | F11: 53.3 | G11: 282.7 | H11: 9.04 | I11: 9.04 | J11: =H11*500/1000 -> 4.52
B12: 8 | C12: 72 | D12: 596.3 | E12: 3140.4 | F12: 74.5 | G12: 392.5 | H12: 12.51 | I12: 12.51 | J12: =H12*500/1000 -> 6.255
B13: 16 | C13: 125 | D13: 1052.3 | E13: 5509.1 | F13: 131.5 | G13: 688.6 | H13: 14.23 | I13: 14.23 | J13: =H13*500/1000 -> 7.115
B14: 32 | C14: 185 | D14: 1553.7 | E14: 8150.3 | F14: 194.2 | G14: 1018.8 | H14: 19.36 | I14: 19.36 | J14: =H14*500/1000 -> 9.68
B15: 64 | C15: 270 | D15: 2233.6 | E15: 11706.1 | F15: 279.2 | G15: 1463.3 | H15: 27.31 | I15: 27.31 | J15: =H15*500/1000 -> 13.655
B16: 128 | C16: 375 | D16: 3141.3 | E16: 16442.6 | F16: 392.7 | G16: 2055.3 | H16: 38.94 | I16: 38.94 | J16: =H16*500/1000 -> 19.47
B20: GB200 Target (20k/.5k)
B21: Concurrency | C21: Request Throughput (req/min) | D21: Output tok/s | E21: Total tok/s | F21: Output tok/s/chip | G21: Total tok/s/chip | H21: Mean TPOT (ms) | I21: Mean ITL (ms | J21: Gen Time (s) (500 tokens)
B22: 1 | C22: 11 | D22: 106 | E22: 4730 | F22: 13.2 | G22: 591.2 | H22: 8.18 | I22: 8.18 | J22: =H22*500/1000 -> 4.09
B23: 2 | C23: 18 | D23: 148.1 | E23: 6664.7 | F23: 18.5 | G23: 833.1 | H23: 10.67 | I23: 10.67 | J23: =H23*500/1000 -> 5.335
B24: 4 | C24: 32 | D24: 265.7 | E24: 11702.1 | F24: 33.2 | G24: 1462.8 | H24: 12.42 | I24: 12.42 | J24: =H24*500/1000 -> 6.21
B25: 8 | C25: 42 | D25: 349.4 | E25: 15248.6 | F25: 43.7 | G25: 1906.1 | H25: 19.86 | I25: 19.86 | J25: =H25*500/1000 -> 9.93
B26: 16 | C26: 52 | D26: 431.6 | E26: 18700 | F26: 54 | G26: 2337.5 | H26: 33.45 | I26: 33.45 | J26: =H26*500/1000 -> 16.725
B27: 32 | C27: 59 | D27: 496.9 | E27: 21584.6 | F27: 62.1 | G27: 2698.1 | H27: 59.89 | I27: 59.89 | J27: =H27*500/1000 -> 29.945
B28: 64 | C28: 61 | D28: 511.6 | E28: 22195.4 | F28: 63.9 | G28: 2774.4 | H28: 95.1 | I28: 95.1 | J28: =H28*500/1000 -> 47.55
B29: 128 | C29: 61 | D29: 520.1 | E29: 22530.1 | F29: 65 | G29: 2816.3 | H29: 95.59 | I29: 95.59 | J29: =H29*500/1000 -> 47.795
C45: Concurrency | D45: Request Throughput (req/min) | E45: P50 Speed (tok/s) | F45: Tokens/s/chip | G45: Inter-Token Latency (ms) | H45: Gen Time (500 tokens)
C46: 1 | D46: 17 | E46: 135 | F46: =D46*500/60/8 -> 17.708333 | G46: =1/E46*1000 -> 7.4074074 | H46: =500/E46 -> 3.7037037
C47: 2 | D47: 28 | E47: 120 | F47: =D47*500/60/8 -> 29.166667 | G47: =1/E47*1000 -> 8.3333333 | H47: =500/E47 -> 4.1666667
C48: 4 | D48: 50 | E48: 108 | F48: =D48*500/60/8 -> 52.083333 | G48: =1/E48*1000 -> 9.2592593 | H48: =500/E48 -> 4.6296296
C49: 8 | D49: 72 | E49: 96 | F49: =D49*500/60/8 -> 75 | G49: =1/E49*1000 -> 10.416667 | H49: =500/E49 -> 5.2083333
C50: 16 | D50: 125 | E50: 78 | F50: =D50*500/60/8 -> 130.20833 | G50: =1/E50*1000 -> 12.820513 | H50: =500/E50 -> 6.4102564
C51: 32 | D51: 185 | E51: 58 | F51: =D51*500/60/8 -> 192.70833 | G51: =1/E51*1000 -> 17.241379 | H51: =500/E51 -> 8.6206897
C52: 64 | D52: 270 | E52: 44 | F52: =D52*500/60/8 -> 281.25 | G52: =1/E52*1000 -> 22.727273 | H52: =500/E52 -> 11.363636
C53: 128 | D53: 375 | E53: 35 | F53: =D53*500/60/8 -> 390.625 | G53: =1/E53*1000 -> 28.571429 | H53: =500/E53 -> 14.285714
C63: GB200 Target (20k/.5k)
C64: Concurrency | D64: Throughput (req/min) | E64: P50 Speed (tok/s) | F64: Tokens/s/chip | G64: ITL (ms) | H64: Gen Time (500 tokens)
C65: 1 | D65: 11 | E65: 123 | F65: =D65*500/60/8 -> 11.458333 | G65: =1/E65*1000 -> 8.1300813 | H65: =500/E65 -> 4.0650407
C66: 2 | D66: 18 | E66: 108 | F66: =D66*500/60/8 -> 18.75 | G66: =1/E66*1000 -> 9.2592593 | H66: =500/E66 -> 4.6296296
C67: 4 | D67: 32 | E67: 98 | F67: =D67*500/60/8 -> 33.333333 | G67: =1/E67*1000 -> 10.204082 | H67: =500/E67 -> 5.1020408
C68: 8 | D68: 42 | E68: 78 | F68: =D68*500/60/8 -> 43.75 | G68: =1/E68*1000 -> 12.820513 | H68: =500/E68 -> 6.4102564
C69: 16 | D69: 52 | E69: 57 | F69: =D69*500/60/8 -> 54.166667 | G69: =1/E69*1000 -> 17.54386 | H69: =500/E69 -> 8.7719298
C70: 32 | D70: 59 | E70: 36 | F70: =D70*500/60/8 -> 61.458333 | G70: =1/E70*1000 -> 27.777778 | H70: =500/E70 -> 13.888889
C71: 64 | D71: 61 | E71: 24 | F71: =D71*500/60/8 -> 63.541667 | G71: =1/E71*1000 -> 41.666667 | H71: =500/E71 -> 20.833333
C72: 128 | D72: 61 | E72: 24 | F72: =D72*500/60/8 -> 63.541667 | G72: =1/E72*1000 -> 41.666667 | H72: =500/E72 -> 20.833333

Sheet Roofline Analysis
A1: Decode
A2: Layers | B2: Component | C2: Theoretical Roofline (ms) | D2: B200 | E2: Baseline (ms) (as of 5/20) | F2: Roofline (% of E2E) | G2: Baseline (% of E2E) | H2: % Theoretical Roofline | I2: % B200 | J2: Debug & Optimization Opportunities
A3: MLA | B3: Q Down Proj + KV Down Proj | C3: ='Decode Last Token'!G57+'Decode Last Token'!G60 -> 0.0019966231 | E3: 0.009205 | F3: =C3/$C$19 -> 0.009294412 | G3: =E3/$E$19 -> 0.014696749 | H3: =C3/E3 -> 0.21690637 | J3: • Quantization • Why are weights in bf16? • Fuse layernorm
B4: Q Up Proj | C4: ='Decode Last Token'!G58 -> 0.0049877167 | E4: 0.0174 | F4: =C4/$C$19 -> 0.023218149 | G4: =E4/$E$19 -> 0.027780927 | H4: =C4/E4 -> 0.28665038 | J4: • Fuse act quant into the fusion
B5: Q Proj to K (K weight absoption) | C5: ='Decode Last Token'!G59 -> 0.0013902452 | E5: 0.006788 | F5: =C5/$C$19 -> 0.0064716829 | G5: =E5/$E$19 -> 0.010837755 | H5: =C5/E5 -> 0.20480926 | J5: • Remove reshape
B6: QK (nope) + QK (rope) + AV | C6: ='Decode Last Token'!G62 -> 0.006084537 | E6: 0.030721 | F6: =C6/$C$19 -> 0.02832392 | G6: =E6/$E$19 -> 0.049049302 | H6: =C6/E6 -> 0.19805791 | J6: • Quantize Q pending quality verification • Try batched RPA • Kernel Tuning • Remove transpose/pad
B7: V Up Proj (Weight Absorption) | C7: ='Decode Last Token'!G67 -> 0.00128852 | E7: 0.004864 | F7: =C7/$C$19 -> 0.0059981451 | G7: =E7/$E$19 -> 0.0077658866 | H7: =C7/E7 -> 0.26490953 | J7: • Matmul is meoery bound. Can we use FP4?
B8: O Proj | C8: ='Decode Last Token'!G69 -> 0.015254551 | E8: 0.042717 | F8: =C8/$C$19 -> 0.071010935 | G8: =E8/$E$19 -> 0.068202175 | H8: =C8/E8 -> 0.35710725
A9: MoE (Routed) | B9: Token Routing | E9: 0.025734 | F9: =C9/$C$19 -> 0 | G9: =E9/$E$19 -> 0.041087033 | H9: =C9/E9 -> 0
B10: Token Permute | E10: 0.015646 | F10: =C10/$C$19 -> 0 | G10: =E10/$E$19 -> 0.024980481 | H10: =C10/E10 -> 0
B11: Dispatch | C11: ='Decode Last Token'!G70 -> 0 | E11: 0.027993 | F11: =C11/$C$19 -> 0 | G11: =E11/$E$19 -> 0.044693763 | H11: =C11/E11 -> 0 | J11: • FP8 AG
B12: Gating x 2 + Act | C12: ='Decode Last Token'!G71 -> 0.12207031 | E12: 0.18 | F12: =C12/$C$19 -> 0.56824533 | G12: =E12/$E$19 -> 0.2873889 | H12: =C12/E12 -> 0.6781684 | J12: • Look into percale traces
B13: Linear | C13: ='Decode Last Token'!G72 -> 0.061747233 | E13: 0.114 | F13: =C13/$C$19 -> 0.28743743 | G13: =E13/$E$19 -> 0.18201297 | H13: =C13/E13 -> 0.5416424 | J13: • down proj gmm contract dim is small, so each shard only has 256 along contract dim. This limits gmm efficieny • 2D EP + TP
B14: Reverse Sort & Unpermte | E14: 0.021753 | F14: =C14/$C$19 -> 0 | G14: =E14/$E$19 -> 0.034730948 | H14: =C14/E14 -> 0
B15: Reduce | E15: 0.008475 | F15: =C15/$C$19 -> 0 | G15: =E15/$E$19 -> 0.013531227 | H15: =C15/E15 -> 0
B16: Collect | C16: ='Decode Last Token'!G73 -> 0 | E16: 0.055802 | F16: =C16/$C$19 -> 0 | G16: =E16/$E$19 -> 0.089093751 | H16: =C16/E16 -> 0 | J16: • AR is too slow • Use hirachial RS • quantization? be careful about the quality
A17: MoE (Shared) | B17: Input | C17: ='Decode Last Token'!H557 -> 0.0076442295 | E17: 0.025424 | F17: =C17/$C$19 -> 0.035584391 | G17: =E17/$E$19 -> 0.040592085 | H17: =C17/E17 -> 0.30066982
B18: Output | C18: ='Decode Last Token'!H595 -> 0.00383589 | E18: 0.013727 | F18: =C18/$C$19 -> 0.01785632 | G18: =E18/$E$19 -> 0.021916597 | H18: =C18/E18 -> 0.27944125
A19: Total | C19: ='Decode Last Token'!G76 -> 0.21481974 | E19: 0.626329 | H19: =C19/E19 -> 0.34298226
A20: Mean ITL (ms) | C20: ='Config and Summary'!B50*1000/500 -> 13.380494 | D20: ='Model info & Targets'!I16 -> 38.94 | E20: ='moved to gomistral-ironwood-wor'!J3 -> 68.72 | H20: =C20/E20 -> 0.19471033 | I20: =D20/E20 -> 0.56664726
A21: Throughput (tok/s/chip) | C21: ='Config and Summary'!B59 -> 1026.8062 | D21: ='Model info & Targets'!F16 -> 392.7 | E21: ='moved to gomistral-ironwood-wor'!I3 -> 197.1925 | H21: =E21/C21 -> 0.19204452 | I21: =E21/D21 -> 0.5021454
A25: Prefill
A26: Layers | B26: Component | C26: Theoretical Roofline (ms) | D26: B200 | E26: Baseline (ms) (as of 5/20) | F26: Roofline (% of E2E) | G26: Baseline (% of E2E) | H26: % Theoretical Roofline | I26: % B200 | J26: Optimization Opportunities
A27: MLA | B27: Q Down Proj + KV Down Proj | C27: =Prefill!G57+Prefill!G60 -> 0.016535624 | E27: 0.086017 | F27: =C27/$C$43 -> 0.012531172 | G27: =E27/$E$43 -> 0.0040758624 | H27: =C27/E27 -> 0.1922367 | J27: • Quantization • Why are weights in bf16? • Fuse layernorm
B28: Q Up Proj | C28: =Prefill!G58 -> 0.041231686 | E28: 0.188 | F28: =C28/$C$43 -> 0.03124656 | G28: =E28/$E$43 -> 0.0089082638 | H28: =C28/E28 -> 0.21931748 | J28: • Fuse act quant into the fusion • Eliminate the sparse core formatting
B29: Q Proj to K (K weight absoption) | C29: =Prefill!G59 -> 0.040147569 | E29: 0.172 | F29: =C29/$C$43 -> 0.030424985 | G29: =E29/$E$43 -> 0.0081501137 | H29: =C29/E29 -> 0.2334161 | J29: • Remove reshape • Remove copies
B30: QK (nope) + QK (rope) + AV | C30: =Prefill!G62 -> 0.62305659 | E30: 3.451 | F30: =C30/$C$43 -> 0.47217024 | G30: =E30/$E$43 -> 0.1635235 | H30: =C30/E30 -> 0.18054378 | J30: • Quantize Q pending quality verification • Try batched RPA • Kernel Tuning • Remove transpose/pad
B31: V Up Proj (Weight Absorption) | C31: =Prefill!G67 -> 0.027126736 | E31: 0.089252 | F31: =C31/$C$43 -> 0.020557422 | G31: =E31/$E$43 -> 0.0042291509 | H31: =C31/E31 -> 0.30393421 | J31: • Matmul is meoery bound. Can we use FP4?
B32: O Proj | C32: =Prefill!G69 -> 0.12827636 | E32: 0.404436 | F32: =C32/$C$43 -> 0.097211519 | G32: =E32/$E$43 -> 0.01916395 | H32: =C32/E32 -> 0.31717344 | J32: • Fuse act quant into the fusion
A33: MoE (Routed) | B33: Token Routing | E33: 0.302 | F33: =C33/$C$43 -> 0 | G33: =E33/$E$43 -> 0.014310083 | H33: =C33/E33 -> 0
B34: Token Permute | E34: 2.132 | F34: =C34/$C$43 -> 0 | G34: =E34/$E$43 -> 0.1010235 | H34: =C34/E34 -> 0 | J34: • Overlap with shared expert | M34: =1.1+0.807 -> 1.907 | N34: =E36+E37 -> 2.75
B35: Dispatch | C35: =Prefill!G70 -> 0 | E35: 1.955 | F35: =C35/$C$43 -> 0 | G35: =E35/$E$43 -> 0.092636467 | H35: =C35/E35 -> 0 | J35: • FP8 AG | N35: =(N34-M34)/N34 -> 0.30654545
B36: Gating x 2 + Act | C36: =Prefill!G71 -> 0.25655271 | E36: 1.5 | F36: =C36/$C$43 -> 0.19442304 | G36: =E36/$E$43 -> 0.071076573 | H36: =C36/E36 -> 0.17103514 | J36: • Look into percale traces
B37: Linear | C37: =Prefill!G72 -> 0.18663194 | E37: 1.25 | F37: =C37/$C$43 -> 0.14143507 | G37: =E37/$E$43 -> 0.059230478 | H37: =C37/E37 -> 0.14930556 | J37: • down proj gmm contract dim is small, so each shard only has 256 along contract dim. This limits gmm efficieny • 2D EP + TP
B38: Reverse Sort & Unpermte | E38: 5.066 | F38: =C38/$C$43 -> 0 | G38: =E38/$E$43 -> 0.24004928 | H38: =C38/E38 -> 0 | J38: • Look into existing SC kernel usage on TP
B39: Reduce | E39: 1.809 | F39: =C39/$C$43 -> 0 | G39: =E39/$E$43 -> 0.085718347 | H39: =C39/E39 -> 0
B40: Collect | C40: =Prefill!G73 -> 0 | E40: 2.383 | F40: =C40/$C$43 -> 0 | G40: =E40/$E$43 -> 0.11291698 | H40: =C40/E40 -> 0 | J40: • AR is too slow • Use hirachial RS • quantization? be careful about the quality
A41: MoE (Shared) | B41: Input | C41: =Prefill!H557 -> 0.013834635 | E41: 0.186 | F41: =C41/$C$43 -> 0.010484285 | G41: =E41/$E$43 -> 0.0088134951 | H41: =C41/E41 -> 0.07437976
B42: Output | C42: =Prefill!H593 -> 0.032069089 | E42: 0.09788 | F42: =C42/$C$43 -> 0.02430288 | G42: =E42/$E$43 -> 0.0046379833 | H42: =C42/E42 -> 0.32763679 | J42: • Fuse the abs_max and clamp • remove concatenate
A43: Total | C43: =SUM(C27:C40) -> 1.3195592 | E43: 21.104 | F43: =C43/$C$43 -> 1 | H43: =C43/E43 -> 0.062526498

Sheet 6_14_checkpoint
A1: Decode
A2: Layers | B2: Component | C2: Theoretical Roofline (ms) | D2: B200 | E2: Baseline (ms) (as of 5/20) | F2: Roofline (% of E2E) | G2: Baseline (% of E2E) | H2: % Theoretical Roofline | I2: % B200 | J2: Debug & Optimization Opportunities
A3: MLA | B3: Q Down Proj + KV Down Proj | C3: ='Decode Last Token'!G57+'Decode Last Token'!G60 -> 0.0019966231 | F3: =C3/$C$19 -> 0.009294412 | G3: =E3/$E$19 -> 0 | H3: =C3/E3 -> #DIV/0! | J3: • Quantization • Why are weights in bf16? • Fuse layernorm
B4: Q Up Proj | C4: ='Decode Last Token'!G58 -> 0.0049877167 | F4: =C4/$C$19 -> 0.023218149 | G4: =E4/$E$19 -> 0 | H4: =C4/E4 -> #DIV/0! | J4: • Fuse act quant into the fusion
B5: Q Proj to K (K weight absoption) | C5: ='Decode Last Token'!G59 -> 0.0013902452 | F5: =C5/$C$19 -> 0.0064716829 | G5: =E5/$E$19 -> 0 | H5: =C5/E5 -> #DIV/0! | J5: • Remove reshape
B6: QK (nope) + QK (rope) + AV | C6: ='Decode Last Token'!G62 -> 0.006084537 | E6: 0.0378 | F6: =C6/$C$19 -> 0.02832392 | G6: =E6/$E$19 -> 0.062582781 | H6: =C6/E6 -> 0.16096659 | J6: • Quantize Q pending quality verification • Try batched RPA • Kernel Tuning • Remove transpose/pad
B7: V Up Proj (Weight Absorption) | C7: ='Decode Last Token'!G67 -> 0.00128852 | F7: =C7/$C$19 -> 0.0059981451 | G7: =E7/$E$19 -> 0 | H7: =C7/E7 -> #DIV/0! | J7: • Matmul is meoery bound. Can we use FP4?
B8: O Proj | C8: ='Decode Last Token'!G69 -> 0.015254551 | F8: =C8/$C$19 -> 0.071010935 | G8: =E8/$E$19 -> 0 | H8: =C8/E8 -> #DIV/0!
A9: MoE (Routed) | B9: Token Routing | E9: 0.04 | F9: =C9/$C$19 -> 0 | G9: =E9/$E$19 -> 0.066225166 | H9: =C9/E9 -> 0
B10: Token Permute | F10: =C10/$C$19 -> 0 | G10: =E10/$E$19 -> 0 | H10: =C10/E10 -> #DIV/0!
B11: Dispatch | C11: ='Decode Last Token'!G70 -> 0 | F11: =C11/$C$19 -> 0 | G11: =E11/$E$19 -> 0 | H11: =C11/E11 -> #DIV/0! | J11: • FP8 AG
B12: Gating x 2 + Act | C12: ='Decode Last Token'!G71 -> 0.12207031 | E12: 0.179 | F12: =C12/$C$19 -> 0.56824533 | G12: =E12/$E$19 -> 0.29635762 | H12: =C12/E12 -> 0.68195705 | J12: • Look into percale traces
B13: Linear | C13: ='Decode Last Token'!G72 -> 0.061747233 | E13: 0.116 | F13: =C13/$C$19 -> 0.28743743 | G13: =E13/$E$19 -> 0.19205298 | H13: =C13/E13 -> 0.53230373 | J13: • down proj gmm contract dim is small, so each shard only has 256 along contract dim. This limits gmm efficieny • 2D EP + TP
B14: Reverse Sort & Unpermte | F14: =C14/$C$19 -> 0 | G14: =E14/$E$19 -> 0 | H14: =C14/E14 -> #DIV/0!
B15: Reduce | F15: =C15/$C$19 -> 0 | G15: =E15/$E$19 -> 0 | H15: =C15/E15 -> #DIV/0!
B16: Collect | C16: ='Decode Last Token'!G73 -> 0 | E16: 0.032 | F16: =C16/$C$19 -> 0 | G16: =E16/$E$19 -> 0.052980132 | H16: =C16/E16 -> 0 | J16: • AR is too slow • Use hirachial RS • quantization? be careful about the quality
A17: MoE (Shared) | B17: Input | C17: ='Decode Last Token'!H557 -> 0.0076442295 | F17: =C17/$C$19 -> 0.035584391 | G17: =E17/$E$19 -> 0 | H17: =C17/E17 -> #DIV/0!
B18: Output | C18: ='Decode Last Token'!H595 -> 0.00383589 | F18: =C18/$C$19 -> 0.01785632 | G18: =E18/$E$19 -> 0 | H18: =C18/E18 -> #DIV/0!
A19: Total | C19: ='Decode Last Token'!G76 -> 0.21481974 | E19: 0.604 | H19: =C19/E19 -> 0.35566182
A20: Mean ITL (ms) | C20: ='Config and Summary'!B50*1000/500 -> 13.380494 | D20: ='Model info & Targets'!I16 -> 38.94 | E20: ='moved to gomistral-ironwood-wor'!J3 -> 68.72 | H20: =C20/E20 -> 0.19471033 | I20: =D20/E20 -> 0.56664726
A21: Throughput (tok/s/chip) | C21: ='Config and Summary'!B59 -> 1026.8062 | D21: ='Model info & Targets'!F16 -> 392.7 | E21: ='moved to gomistral-ironwood-wor'!I3 -> 197.1925 | H21: =E21/C21 -> 0.19204452 | I21: =E21/D21 -> 0.5021454
A25: Prefill
A26: Layers | B26: Component | C26: Theoretical Roofline (ms) | D26: B200 | E26: Baseline (ms) (as of 5/20) | F26: Roofline (% of E2E) | G26: Baseline (% of E2E) | H26: % Theoretical Roofline | I26: % B200 | J26: Optimization Opportunities
A27: MLA | B27: Q Down Proj + KV Down Proj | C27: =Prefill!G57+Prefill!G60 -> 0.016535624 | F27: =C27/$C$43 -> 0.012531172 | G27: =E27/$E$43 -> 0 | H27: =C27/E27 -> #DIV/0! | J27: • Quantization • Why are weights in bf16? • Fuse layernorm
B28: Q Up Proj | C28: =Prefill!G58 -> 0.041231686 | F28: =C28/$C$43 -> 0.03124656 | G28: =E28/$E$43 -> 0 | H28: =C28/E28 -> #DIV/0! | J28: • Fuse act quant into the fusion • Eliminate the sparse core formatting
B29: Q Proj to K (K weight absoption) | C29: =Prefill!G59 -> 0.040147569 | F29: =C29/$C$43 -> 0.030424985 | G29: =E29/$E$43 -> 0 | H29: =C29/E29 -> #DIV/0! | J29: • Remove reshape • Remove copies
B30: QK (nope) + QK (rope) + AV | C30: =Prefill!G62 -> 0.62305659 | E30: 2 | F30: =C30/$C$43 -> 0.47217024 | G30: =E30/$E$43 -> 0.10869565 | H30: =C30/E30 -> 0.31152829 | J30: • Quantize Q pending quality verification • Try batched RPA • Kernel Tuning • Remove transpose/pad
B31: V Up Proj (Weight Absorption) | C31: =Prefill!G67 -> 0.027126736 | F31: =C31/$C$43 -> 0.020557422 | G31: =E34/$E$43 -> 0.11956522 | H31: =C31/E34 -> 0.012330335 | J31: • Matmul is meoery bound. Can we use FP4?
B32: O Proj | C32: =Prefill!G69 -> 0.12827636 | F32: =C32/$C$43 -> 0.097211519 | G32: =E32/$E$43 -> 0 | H32: =C32/E32 -> #DIV/0! | J32: • Fuse act quant into the fusion
A33: MoE (Routed) | B33: Token Routing | F33: =C33/$C$43 -> 0 | G33: =E33/$E$43 -> 0 | H33: =C33/E33 -> #DIV/0!
B34: Token Permute | E34: 2.2 | F34: =C34/$C$43 -> 0 | G34: =E34/$E$43 -> 0.11956522 | H34: =C34/E34 -> 0 | J34: • Overlap with shared expert | M34: =1.1+0.807 -> 1.907 | N34: =E36+E37 -> 1.969
B35: Dispatch | C35: =Prefill!G70 -> 0 | E35: 1.186 | F35: =C35/$C$43 -> 0 | G35: =E35/$E$43 -> 0.064456522 | H35: =C35/E35 -> 0 | J35: • FP8 AG | N35: =(N34-M34)/N34 -> 0.031488065
B36: Gating x 2 + Act | C36: =Prefill!G71 -> 0.25655271 | E36: 1.14 | F36: =C36/$C$43 -> 0.19442304 | G36: =E36/$E$43 -> 0.061956522 | H36: =C36/E36 -> 0.22504624 | J36: • Look into percale traces
B37: Linear | C37: =Prefill!G72 -> 0.18663194 | E37: 0.829 | F37: =C37/$C$43 -> 0.14143507 | G37: =E37/$E$43 -> 0.045054348 | H37: =C37/E37 -> 0.225129 | J37: • down proj gmm contract dim is small, so each shard only has 256 along contract dim. This limits gmm efficieny • 2D EP + TP
B38: Reverse Sort & Unpermte | E38: 5 | F38: =C38/$C$43 -> 0 | G38: =E38/$E$43 -> 0.27173913 | H38: =C38/E38 -> 0 | J38: • Look into existing SC kernel usage on TP
B39: Reduce | E39: 1.8 | F39: =C39/$C$43 -> 0 | G39: =E39/$E$43 -> 0.097826087 | H39: =C39/E39 -> 0
B40: Collect | C40: =Prefill!G73 -> 0 | E40: 2.393 | F40: =C40/$C$43 -> 0 | G40: =E40/$E$43 -> 0.13005435 | H40: =C40/E40 -> 0 | J40: • AR is too slow • Use hirachial RS • quantization? be careful about the quality
A41: MoE (Shared) | B41: Input | C41: =Prefill!H557 -> 0.013834635 | F41: =C41/$C$43 -> 0.010484285 | G41: =E41/$E$43 -> 0 | H41: =C41/E41 -> #DIV/0!
B42: Output | C42: =Prefill!H593 -> 0.032069089 | F42: =C42/$C$43 -> 0.02430288 | G42: =E42/$E$43 -> 0 | H42: =C42/E42 -> #DIV/0! | J42: • Fuse the abs_max and clamp • remove concatenate
A43: Total | C43: =SUM(C27:C40) -> 1.3195592 | E43: 18.4 | F43: =C43/$C$43 -> 1 | H43: =C43/E43 -> 0.071715175

Sheet simulator
A1: layers | B1: 61
B2: step time from xprof (ms) | C2: e2e latency | D2: # of Tokens | E2: Throughput (tokens/s/chip) | F2: QPS/chip
A3: prefill | B3: =21.1*1 -> 21.1 | C3: =B3/1000*$B$1 -> 1.2871 | D3: =2048*16 -> 32768 | E3: =D3/C3/8 -> 3182.3479 | F3: =E3/2048 -> 1.5538808
A4: decode | B4: =0.626*1 -> 0.626 | C4: =B4/1000*$B$1 -> 0.038186 | D4: =128*1 -> 128 | E4: =D4/C4/8 -> 419.00173 | F4: =E4/512 -> 0.81836275
A5: output | E5: =1/(1/F3 + 1/F4) * 512 -> 274.45696

Sheet Config and Summary
B1: Preset Selection: | C1: [2k/.5k] GB200 4-chip DP8/TP8 Aggregated MOE-a8a8 B=128 | F1: [2k/.5k] GF 2x2 DP8/EP8 Aggregated MOE-a8w8 B=32 | H1: [2k/.5k] GF 2x2x2 DP16/TP16 Aggregated MOE-a8a8 B=128 | J1: [2k/.5k] GF 4x4 DP32/EP32 Aggregated MOE-a8w8 | L1: [20k/.5k] GF 2x2 DP8/EP8 Aggregated MOE-a8w8 B=32 | N1: [20k/.5k] GF 2x2x2 DP8/EP8 Aggregated MOE-a8w8 B=128 | P1: [20k/.5k] GF 4x4 DP8/EP8 Aggregated MOE-a8w8 B=32 | R1: [2k/.5k] GB200 4-chip DP8/TP8 Aggregated MOE-a8a8 B=128
C2: Decode | D2: Prefill | F2: Decode | G2: Prefill | H2: Decode | I2: Prefill | J2: Decode | K2: Prefill | L2: Decode | M2: Prefill | N2: Decode | O2: Prefill | P2: Decode | Q2: Prefill | R2: Decode | S2: Prefill
A3: Device Assumptions
A4: Chip Name | C4: =XLOOKUP($C$1, $F$1:$U$1, F4:U4) -> GB200 Derated | D4: =XLOOKUP($C$1, $F$1:$U$1, G4:V4) -> GB200 Derated | F4: GhostFish (P3) Derated | G4: GhostFish (P3) Derated | H4: GhostFish (P3) Derated | I4: GhostFish (P3) Derated | J4: GhostFish (P3) Derated | K4: GhostFish (P3) Derated | L4: GhostFish (P3) Derated | M4: GhostFish (P3) Derated | N4: GhostFish (P3) Derated | O4: GhostFish (P3) Derated | P4: GhostFish (P3) Derated | Q4: GhostFish (P3) Derated | R4: GB200 Derated | S4: GB200 Derated
A5: Use Measured NCCL Lookup Table | C5: =XLOOKUP($C$1, $F$1:$U$1, F5:U5) -> TRUE | D5: =XLOOKUP($C$1, $F$1:$U$1, G5:V5) -> TRUE | F5: FALSE | G5: FALSE | H5: FALSE | I5: FALSE | J5: FALSE | K5: FALSE | L5: FALSE | M5: FALSE | N5: FALSE | O5: FALSE | P5: FALSE | Q5: FALSE | R5: TRUE | S5: TRUE
C6: =XLOOKUP($C$1, $F$1:$U$1, F6:U6) | D6: =XLOOKUP($C$1, $F$1:$U$1, G6:V6)
A7: Sharding (Axis Name, # of Devices) | C7: =XLOOKUP($C$1, $F$1:$U$1, F7:U7) | D7: =XLOOKUP($C$1, $F$1:$U$1, G7:V7)
A8: model | C8: =XLOOKUP($C$1, $F$1:$U$1, F8:U8) -> 1 | D8: =XLOOKUP($C$1, $F$1:$U$1, G8:V8) -> 1 | F8: 1 | G8: 1 | H8: 1 | I8: 1 | J8: 1 | K8: 1 | L8: 1 | M8: 1 | N8: 1 | O8: 1 | P8: 1 | Q8: 1 | R8: 1 | S8: 1
A9: data | C9: =XLOOKUP($C$1, $F$1:$U$1, F9:U9) -> 8 | D9: =XLOOKUP($C$1, $F$1:$U$1, G9:V9) -> 8 | F9: 8 | G9: 8 | H9: 16 | I9: 16 | J9: 32 | K9: 32 | L9: 8 | M9: 8 | N9: 16 | O9: 16 | P9: 32 | Q9: 32 | R9: 8 | S9: 8
A10: seq | C10: =XLOOKUP($C$1, $F$1:$U$1, F10:U10) -> 1 | D10: =XLOOKUP($C$1, $F$1:$U$1, G10:V10) -> 1 | F10: 1 | G10: 1 | H10: 1 | I10: 1 | J10: 1 | K10: 1 | L10: 1 | M10: 1 | N10: 1 | O10: 1 | P10: 1 | Q10: 1 | R10: 1 | S10: 1
A11: attn_model | C11: =XLOOKUP($C$1, $F$1:$U$1, F11:U11) -> 1 | D11: =XLOOKUP($C$1, $F$1:$U$1, G11:V11) -> 1 | F11: 1 | G11: 1 | H11: 1 | I11: 1 | J11: 1 | K11: 1 | L11: 1 | M11: 1 | N11: 1 | O11: 1 | P11: 1 | Q11: 1 | R11: 1 | S11: 1
C12: =XLOOKUP($C$1, $F$1:$U$1, F12:U12) | D12: =XLOOKUP($C$1, $F$1:$U$1, G12:V12)
A13: Serving Configuration and Strategy | C13: =XLOOKUP($C$1, $F$1:$U$1, F13:U13) | D13: =XLOOKUP($C$1, $F$1:$U$1, G13:V13)
A14: Sequence Length (Q) | B14: T | C14: =XLOOKUP($C$1, $F$1:$U$1, F14:U14) -> 1 | D14: =XLOOKUP($C$1, $F$1:$U$1, G14:V14) -> 2048 | F14: 1 | G14: 2048 | H14: 1 | I14: 2048 | J14: 1 | K14: 2048 | L14: 1 | M14: 20480 | N14: 1 | O14: 20480 | P14: 1 | Q14: 20480 | R14: 1 | S14: 2048
A15: Batch Size (power of 2) | B15: B | C15: =XLOOKUP($C$1, $F$1:$U$1, F15:U15) -> 128 | D15: =XLOOKUP($C$1, $F$1:$U$1, G15:V15) -> 8 | F15: 32 | G15: 8 | H15: 128 | I15: 16 | J15: 128 | K15: 32 | L15: 32 | M15: 8 | N15: 128 | O15: 16 | P15: 128 | Q15: 32 | R15: 128 | S15: 8
A16: Sequence Length (KV) | B16: S | C16: =XLOOKUP($C$1, $F$1:$U$1, F16:U16) -> 2560 | D16: =XLOOKUP($C$1, $F$1:$U$1, G16:V16) -> 2048 | F16: =G16+512 -> 2560 | G16: =G14 -> 2048 | H16: =I16+512 -> 2560 | I16: =I14 -> 2048 | J16: =K16+512 -> 2560 | K16: =K14 -> 2048 | L16: =M16+512 -> 20992 | M16: =M14 -> 20480 | N16: =O16+512 -> 20992 | O16: =O14 -> 20480 | P16: =Q16+512 -> 20992 | Q16: =Q14 -> 20480 | R16: =S16+512 -> 2560 | S16: =S14 -> 2048
A17: Sequence Length (KV) - First Token Decode | B17: S_first | C17: =XLOOKUP($C$1, $F$1:$U$1, F17:U17) -> 2048 | D17: =XLOOKUP($C$1, $F$1:$U$1, G17:V17) -> N/A | F17: 2048 | G17: N/A | H17: 2048 | I17: N/A | J17: 2048 | K17: N/A | L17: 20480 | M17: N/A | N17: 20480 | O17: N/A | P17: 20480 | Q17: N/A | R17: 2048 | S17: N/A
A18: Scheduler Latency Overhead | C18: =XLOOKUP($C$1, $F$1:$U$1, F18:U18) -> 0 | D18: =XLOOKUP($C$1, $F$1:$U$1, G18:V18) -> 0 | F18: 0 | G18: 0 | H18: 0 | I18: 0 | J18: 0 | K18: 0 | L18: 0 | M18: 0 | N18: 0 | O18: 0 | P18: 0 | Q18: 0 | R18: 0 | S18: 0
A19: Roofline Discount Rate | C19: =XLOOKUP($C$1, $F$1:$U$1, F19:U19) -> 1 | D19: =XLOOKUP($C$1, $F$1:$U$1, G19:V19) -> 1 | F19: 1 | G19: 1 | H19: 1 | I19: 1 | J19: 1 | K19: 1 | L19: 1 | M19: 1 | N19: 1 | O19: 1 | P19: 1 | Q19: 1 | R19: 1 | S19: 1
A20: Flash Attention Enabled | B20: flash_attn | C20: =XLOOKUP($C$1, $F$1:$U$1, F20:U20) -> TRUE | D20: =XLOOKUP($C$1, $F$1:$U$1, G20:V20) -> TRUE | F20: TRUE | G20: TRUE | H20: TRUE | I20: TRUE | J20: TRUE | K20: TRUE | L20: TRUE | M20: TRUE | N20: TRUE | O20: TRUE | P20: TRUE | Q20: TRUE | R20: TRUE | S20: TRUE
A21: Enforce Perfect Expert Routing | B21: enforce_perfect_expert_routing | C21: =XLOOKUP($C$1, $F$1:$U$1, F21:U21) -> TRUE | D21: =XLOOKUP($C$1, $F$1:$U$1, G21:V21) -> TRUE | F21: TRUE | G21: TRUE | H21: TRUE | I21: TRUE | J21: TRUE | K21: TRUE | L21: TRUE | M21: TRUE | N21: TRUE | O21: TRUE | P21: TRUE | Q21: TRUE | R21: TRUE | S21: TRUE
A22: MOE Token Dispatch Strategy | C22: =XLOOKUP($C$1, $F$1:$U$1, F22:U22) -> Strategy C: Hirarachical All-Gather | D22: =XLOOKUP($C$1, $F$1:$U$1, G22:V22) -> Strategy C: Hirarachical All-Gather | F22: Strategy C: Hirarachical All-Gather | G22: Strategy C: Hirarachical All-Gather | H22: Strategy C: Hirarachical All-Gather | I22: Strategy C: Hirarachical All-Gather | J22: Strategy C: Hirarachical All-Gather | K22: Strategy C: Hirarachical All-Gather | L22: Strategy C: Hirarachical All-Gather | M22: Strategy C: Hirarachical All-Gather | N22: Strategy C: Hirarachical All-Gather | O22: Strategy C: Hirarachical All-Gather | P22: Strategy C: Hirarachical All-Gather | Q22: Strategy C: Hirarachical All-Gather | R22: Strategy C: Hirarachical All-Gather | S22: Strategy C: Hirarachical All-Gather
A23: MOE Token Collect Strategy | C23: =XLOOKUP($C$1, $F$1:$U$1, F23:U23) -> Option C: Hierachical RS | D23: =XLOOKUP($C$1, $F$1:$U$1, G23:V23) -> Option C: Hierachical RS | F23: Option C: Hierachical RS | G23: Option C: Hierachical RS | H23: Option C: Hierachical RS | I23: Option C: Hierachical RS | J23: Option C: Hierachical RS | K23: Option C: Hierachical RS | L23: Option C: Hierachical RS | M23: Option C: Hierachical RS | N23: Option C: Hierachical RS | O23: Option C: Hierachical RS | P23: Option C: Hierachical RS | Q23: Option C: Hierachical RS | R23: Option C: Hierachical RS | S23: Option C: Hierachical RS
A24: MOE Collective Overlap Strategy | C24: =XLOOKUP($C$1, $F$1:$U$1, F24:U24) -> OptionA. No Overlapping | D24: =XLOOKUP($C$1, $F$1:$U$1, G24:V24) -> OptionA. No Overlapping | F24: OptionA. No Overlapping | G24: OptionA. No Overlapping | H24: OptionA. No Overlapping | I24: OptionA. No Overlapping | J24: OptionA. No Overlapping | K24: OptionA. No Overlapping | L24: OptionA. No Overlapping | M24: OptionA. No Overlapping | N24: OptionA. No Overlapping | O24: OptionA. No Overlapping | P24: OptionA. No Overlapping | Q24: OptionA. No Overlapping | R24: OptionA. No Overlapping | S24: OptionA. No Overlapping
C25: =XLOOKUP($C$1, $F$1:$U$1, F25:U25) | D25: =XLOOKUP($C$1, $F$1:$U$1, G25:V25)
A26: Numerics | C26: =XLOOKUP($C$1, $F$1:$U$1, F26:U26) | D26: =XLOOKUP($C$1, $F$1:$U$1, G26:V26)
A27: KV Cache dtype | B27: kv_dtype | C27: =XLOOKUP($C$1, $F$1:$U$1, F27:U27) -> fp8 | D27: =XLOOKUP($C$1, $F$1:$U$1, G27:V27) -> fp8 | F27: fp8 | G27: fp8 | H27: fp8 | I27: fp8 | J27: fp8 | K27: fp8 | L27: fp8 | M27: fp8 | N27: fp8 | O27: fp8 | P27: fp8 | Q27: fp8 | R27: fp8 | S27: fp8
A28: Attention Projections Numeric | B28: attn_proj_dtype | C28: =XLOOKUP($C$1, $F$1:$U$1, F28:U28) -> w8a8 | D28: =XLOOKUP($C$1, $F$1:$U$1, G28:V28) -> w8a8 | F28: w8a8 | G28: w8a8 | H28: w8a8 | I28: w8a8 | J28: w8a8 | K28: w8a8 | L28: w8a8 | M28: w8a8 | N28: w8a8 | O28: w8a8 | P28: w8a8 | Q28: w8a8 | R28: w8a8 | S28: w8a8
A29: Attention Output Projection Numerics | B29: attn_oproj_dtype | C29: =XLOOKUP($C$1, $F$1:$U$1, F29:U29) -> w8a8 | D29: =XLOOKUP($C$1, $F$1:$U$1, G29:V29) -> w8a8 | F29: w8a8 | G29: w8a8 | H29: w8a8 | I29: w8a8 | J29: w8a8 | K29: w8a8 | L29: w8a8 | M29: w8a8 | N29: w8a8 | O29: w8a8 | P29: w8a8 | Q29: w8a8 | R29: w8a8 | S29: w8a8
A30: Attention "K" numeric from KV | B30: attn_kv_k_dtype | C30: =XLOOKUP($C$1, $F$1:$U$1, F30:U30) -> bf16 | D30: =XLOOKUP($C$1, $F$1:$U$1, G30:V30) -> bf16 | F30: bf16 | G30: bf16 | H30: bf16 | I30: bf16 | J30: bf16 | K30: bf16 | L30: bf16 | M30: bf16 | N30: bf16 | O30: bf16 | P30: bf16 | Q30: bf16 | R30: bf16 | S30: bf16
A31: Attention "A" numeric from AV | B31: attn_av_a_dtype | C31: =XLOOKUP($C$1, $F$1:$U$1, F31:U31) -> bf16 | D31: =XLOOKUP($C$1, $F$1:$U$1, G31:V31) -> bf16 | F31: bf16 | G31: bf16 | H31: bf16 | I31: bf16 | J31: bf16 | K31: bf16 | L31: bf16 | M31: bf16 | N31: bf16 | O31: bf16 | P31: bf16 | Q31: bf16 | R31: bf16 | S31: bf16
A32: Expert Dispatch Numeric | B32: expert_dispatch_dtype | C32: =XLOOKUP($C$1, $F$1:$U$1, F32:U32) -> fp8 | D32: =XLOOKUP($C$1, $F$1:$U$1, G32:V32) -> fp8 | F32: fp8 | G32: fp8 | H32: fp8 | I32: fp8 | J32: fp8 | K32: fp8 | L32: fp8 | M32: fp8 | N32: fp8 | O32: fp8 | P32: fp8 | Q32: fp8 | R32: fp8 | S32: fp8
A33: MoE Numeric | B33: moe_dtype | C33: =XLOOKUP($C$1, $F$1:$U$1, F33:U33) -> w8a8 | D33: =XLOOKUP($C$1, $F$1:$U$1, G33:V33) -> w8a8 | F33: w8a8 | G33: w8a8 | H33: w8a8 | I33: w8a8 | J33: w8a8 | K33: w8a8 | L33: w8a8 | M33: w8a8 | N33: w8a8 | O33: w8a8 | P33: w8a8 | Q33: w8a8 | R33: w8a8 | S33: w8a8
A34: Expert Collect Numeric | B34: expert_collect_dtype | C34: =XLOOKUP($C$1, $F$1:$U$1, F34:U34) -> bf16 | D34: =XLOOKUP($C$1, $F$1:$U$1, G34:V34) -> bf16 | F34: bf16 | G34: bf16 | H34: bf16 | I34: bf16 | J34: bf16 | K34: bf16 | L34: bf16 | M34: bf16 | N34: bf16 | O34: bf16 | P34: bf16 | Q34: bf16 | R34: bf16 | S34: bf16
A36: Results
B38: Decode - First Token | C38: Decode - Last Token | D38: Prefill
A39: Memory Occupancy OK | B39: ='Decode First Token'!B94 -> TRUE | C39: ='Decode Last Token'!B94 -> TRUE | D39: =Prefill!B94 -> TRUE
A40: E2E Latency (s) | B40: ='Decode First Token'!B48 -> 0.013029773 | C40: ='Decode Last Token'!B48 -> 0.013104004 | D40: =Prefill!B48 -> 0.080493112
A41: Throughput (tokens/s) | B41: ='Decode First Token'!B49 -> 9823.6557 | C41: ='Decode Last Token'!B49 -> 9768.0068 | D41: =Prefill!B49 -> 203545.37
A42: Discounted Throughput (tokens/s) | B42: ='Decode First Token'!B50 -> 9823.6557 | C42: ='Decode Last Token'!B50 -> 9768.0068 | D42: =Prefill!B50 -> 203545.37
...

Sheet Decode First Token
A1: Contact: donghyun@, gpolovets@, miliu@. Feedback/Bug reports are welcome!
A2: Description | B2: Symbol | C2: Value | F2: Sharding (Axis Name) | G2: # of Devices | H2: Notes | Q2: Size In Bytes | T2: MXU dtype
A3: Embedding Dimension | B3: D | C3: 7168 | F3: [ ↓ Configurable Values] | Q3: fp4 | R3: 0.5 | T3: =U3&","&V3 -> fp4,fp4 | U3: fp4 | V3: fp4 | W3: fp4
A4: Hidden Dimension | B4: F | C4: 4096 | F4: model | G4: ='Config and Summary'!$C8 -> 1 | Q4: fp8 | R4: 1 | T4: =U4&","&V4 -> fp4,fp8 | U4: fp4 | V4: fp8 | W4: fp8
A5: # of experts | B5: E | C5: 128 | F5: data | G5: ='Config and Summary'!$C9 -> 8 | H5: Also used for expert sharding for MoE | Q5: bf16 | R5: 2 | T5: =U5&","&V5 -> fp4,bf16 | U5: fp4 | V5: bf16 | W5: bf16
A6: # of Layers | B6: L | C6: 61 | F6: seq | G6: ='Config and Summary'!$C10 -> 1 | T6: =U6&","&V6 -> fp8,fp4 | U6: fp8 | V6: fp4 | W6: fp8
A7: # of Dense Layers | B7: DL | C7: 3 | F7: attn_model | G7: ='Config and Summary'!$C11 -> 1 | H7: Used if attention is replicated | T7: =U7&","&V7 -> fp8,fp8 | U7: fp8 | V7: fp8 | W7: fp8
A8: # of experts to be activated per token | B8: top_k | C8: 4 | F8: [ ↓ Derived Values]
A9: The dimension of the compressed latent vector for Query | B9: c_q | C9: 1536 | F9: data,model | G9: =G5*G4 -> 8 | T9: =U9&","&V9 -> fp8,bf16 | U9: fp8 | V9: bf16 | W9: bf16
A10: The dimension of the compressed latent vector for KV | B10: c_kv | C10: 512 | F10: Total # of devices | G10: =PRODUCT(G3:G6) -> 8 | T10: =U10&","&V10 -> bf16,fp4 | U10: bf16 | V10: fp4 | W10: bf16
A11: The dimension of Non-RoPE part of the query head | B11: h_nope | C11: 128 | F11: Total # of chips | G11: =$G$10/$H$18 -> 8 | T11: =U11&","&V11 -> bf16,fp8 | U11: bf16 | V11: fp8 | W11: bf16
A12: The dimension of the RoPE part of the query head | B12: h_rope | C12: 64 | T12: bf16,bf16 | U12: bf16 | V12: bf16 | W12: bf16
A13: The number of Attention Heads (Query) | B13: n_q | C13: 128
A14: [ ↓ Derived parameters]
A15: h_nope+h_rope | B15: h_nope+h_rope | C15: =$C$11+$C$12 -> 192
A16: c_kv+h_rope | B16: c_kv+h_rope | C16: =$C$10+$C$12 -> 576
A17: # of Duplicated tokens (top_k times) | B17: kT | C17: =C8*$C$25 -> 4 | F17: Hardware Spec | H17: ='Config and Summary'!C4 -> GB200 Derated
A18: # of Devices | B18: num_devices | C18: =$G$10 -> 8 | F18: {=DB!A2:A16} -> # of TensorCore per Chip | H18: {=xlookup($H$17,DB!1:1,DB!2:16)} -> 1
A19: # of Chips | B19: num_chips | C19: =$G$11 -> 8 | F19: Per-Chip HBM-BW (GB/s) | H19: 7200
A20: [TPU] Assumed Topology | B20: topo | C20: =vlookup(C19, DB!$A$26:$F$31, 5, False) -> 2x2x2 | F20: Per-Chip TFLOPS (fp4) | H20: 7500
A21: [TPU] Total # of Bidir Links | B21: num_links_in_topo | C21: =vlookup(C19, DB!$A$26:$F$31, 6, False) -> 12 | F21: Per-Chip TFLOPS (fp8) | H21: 3750
F22: Per-Chip TFLOPS (fp16) | H22: 1875
A23: [ ↓ Configurable parameters] | F23: Per-Chip HBM Capacity (GiB) | H23: 179
A24: Regime | B24: R | C24: Decode | F24: Per-Core HBM-BW (GB/s) | H24: 7200
A25: Sequence Length (Q) | B25: T | C25: ='Config and Summary'!C14 -> 1 | F25: Per-Core TFLOPS (fp4) | H25: 7500
A26: Batch Size (power of 2) | B26: B | C26: ='Config and Summary'!C15 -> 128 | F26: Per-Core TFLOPS (fp8) | H26: 3750
A27: Sequence Length (KV) | B27: S | C27: ='Config and Summary'!C17 -> 2048 | D27: Use the first token KV length | F27: Per-Core TFLOPS (bf16) | H27: 1875
A28: Scheduler Latency Overhead | C28: ='Config and Summary'!C18 -> 0 | F28: Per-Core HBM Capacity (GiB) | H28: 179
A29: Roofline Discount Rate | C29: ='Config and Summary'!C19 -> 1 | F29: Core-to-Core ICI Bandwidth (uni, GB/s) | H29: 900
A30: Flash Attention Enabled | B30: flash_attn | C30: ='Config and Summary'!C20 -> TRUE | F30: Chip-to-Chip ICI Bandwidth (uni, GB/s) | H30: 900
A31: Enforce Perfect Expert Routing | B31: enforce_perfect_expert_routing | C31: ='Config and Summary'!C21 -> TRUE | F31: Chip-to-Chip ICI Latency (ms) | H31: 0
A32: [ ↓ Configurable Numeric] | F32: Min MXU Contracting Dim | H32: 1
A33: KV Cache dtype | B33: kv_dtype | C33: ='Config and Summary'!C27 -> fp8
A34: Attention Projections Numeric | B34: attn_proj_dtype | C34: ='Config and Summary'!C28 -> w8a8
A35: Attention Output Projection Numerics | B35: attn_oproj_dtype | C35: ='Config and Summary'!C29 -> w8a8
A36: Attention "K" numeric from KV | B36: attn_kv_k_dtype | C36: ='Config and Summary'!C30 -> bf16
A37: Attention "A" numeric from AV | B37: attn_av_a_dtype | C37: ='Config and Summary'!C31 -> bf16
A38: Expert Dispatch Numeric | B38: expert_dispatch_dtype | C38: ='Config and Summary'!C32 -> fp8
A39: MoE Numeric | B39: moe_dtype | C39: ='Config and Summary'!C33 -> w8a8
A40: Expert Collect Numeric | B40: expert_collect_dtype | C40: ='Config and Summary'!C34 -> bf16
...

Sheet Decode Last Token
A1: Contact: donghyun@, gpolovets@, miliu@. Feedback/Bug reports are welcome!
A2: Description | B2: Symbol | C2: Value | F2: Sharding (Axis Name) | G2: # of Devices | H2: Notes | Q2: Size In Bytes | T2: MXU dtype
A3: Embedding Dimension | B3: D | C3: 7168 | F3: [ ↓ Configurable Values] | Q3: fp4 | R3: 0.5 | T3: =U3&","&V3 -> fp4,fp4 | U3: fp4 | V3: fp4 | W3: fp4
A4: Hidden Dimension | B4: F | C4: 4096 | F4: model | G4: ='Config and Summary'!$C8 -> 1 | Q4: fp8 | R4: 1 | T4: =U4&","&V4 -> fp4,fp8 | U4: fp4 | V4: fp8 | W4: fp8
A5: # of experts | B5: E | C5: 128 | F5: data | G5: ='Config and Summary'!$C9 -> 8 | H5: Also used for expert sharding for MoE | Q5: bf16 | R5: 2 | T5: =U5&","&V5 -> fp4,bf16 | U5: fp4 | V5: bf16 | W5: bf16
A6: # of Layers | B6: L | C6: 61 | F6: seq | G6: ='Config and Summary'!$C10 -> 1 | T6: =U6&","&V6 -> fp8,fp4 | U6: fp8 | V6: fp4 | W6: fp8
A7: # of Dense Layers | B7: DL | C7: 3 | F7: attn_model | G7: ='Config and Summary'!$C11 -> 1 | H7: Used if attention is replicated | T7: =U7&","&V7 -> fp8,fp8 | U7: fp8 | V7: fp8 | W7: fp8
A8: # of experts to be activated per token | B8: top_k | C8: 4 | F8: [ ↓ Derived Values]
A9: The dimension of the compressed latent vector for Query | B9: c_q | C9: 1536 | F9: data,model | G9: =G5*G4 -> 8 | T9: =U9&","&V9 -> fp8,bf16 | U9: fp8 | V9: bf16 | W9: bf16
A10: The dimension of the compressed latent vector for KV | B10: c_kv | C10: 512 | F10: Total # of devices | G10: =PRODUCT(G3:G6) -> 8 | T10: =U10&","&V10 -> bf16,fp4 | U10: bf16 | V10: fp4 | W10: bf16
A11: The dimension of Non-RoPE part of the query head | B11: h_nope | C11: 128 | F11: Total # of chips | G11: =$G$10/$H$18 -> 8 | T11: =U11&","&V11 -> bf16,fp8 | U11: bf16 | V11: fp8 | W11: bf16
A12: The dimension of the RoPE part of the query head | B12: h_rope | C12: 64 | T12: bf16,bf16 | U12: bf16 | V12: bf16 | W12: bf16
A13: The number of Attention Heads (Query) | B13: n_q | C13: 128
A14: [ ↓ Derived parameters]
A15: h_nope+h_rope | B15: h_nope+h_rope | C15: =$C$11+$C$12 -> 192
A16: c_kv+h_rope | B16: c_kv+h_rope | C16: =$C$10+$C$12 -> 576
A17: # of Duplicated tokens (top_k times) | B17: kT | C17: =C8*$C$25 -> 4 | F17: Hardware Spec | H17: ='Config and Summary'!C4 -> GB200 Derated
A18: # of Devices | B18: num_devices | C18: =$G$10 -> 8 | F18: {=DB!A2:A16} -> # of TensorCore per Chip | H18: {=xlookup($H$17,DB!1:1,DB!2:16)} -> 1
A19: # of Chips | B19: num_chips | C19: =$G$11 -> 8 | F19: Per-Chip HBM-BW (GB/s) | H19: 7200
A20: [TPU] Assumed Topology | B20: topo | C20: =vlookup(C19, DB!$A$26:$F$31, 5, False) -> 2x2x2 | F20: Per-Chip TFLOPS (fp4) | H20: 7500
A21: [TPU] Total # of Bidir Links | B21: num_links_in_topo | C21: =vlookup(C19, DB!$A$26:$F$31, 6, False) -> 12 | F21: Per-Chip TFLOPS (fp8) | H21: 3750
F22: Per-Chip TFLOPS (fp16) | H22: 1875
A23: [ ↓ Configurable parameters] | F23: Per-Chip HBM Capacity (GiB) | H23: 179
A24: Regime | B24: R | C24: Decode | F24: Per-Core HBM-BW (GB/s) | H24: 7200
A25: Sequence Length (Q) | B25: T | C25: ='Config and Summary'!C14 -> 1 | F25: Per-Core TFLOPS (fp4) | H25: 7500
A26: Batch Size (power of 2) | B26: B | C26: ='Config and Summary'!C15 -> 128 | F26: Per-Core TFLOPS (fp8) | H26: 3750
A27: Sequence Length (KV) | B27: S | C27: ='Config and Summary'!C16 -> 2560 | F27: Per-Core TFLOPS (bf16) | H27: 1875
A28: Scheduler Latency Overhead | C28: ='Config and Summary'!C18 -> 0 | F28: Per-Core HBM Capacity (GiB) | H28: 179
A29: Roofline Discount Rate | C29: ='Config and Summary'!C19 -> 1 | F29: Core-to-Core ICI Bandwidth (uni, GB/s) | H29: 900
A30: Flash Attention Enabled | B30: flash_attn | C30: ='Config and Summary'!C20 -> TRUE | F30: Chip-to-Chip ICI Bandwidth (uni, GB/s) | H30: 900
A31: Enforce Perfect Expert Routing | B31: enforce_perfect_expert_routing | C31: ='Config and Summary'!C21 -> TRUE | F31: Chip-to-Chip ICI Latency (ms) | H31: 0
A32: [ ↓ Configurable Numeric] | F32: Min MXU Contracting Dim | H32: 1
A33: KV Cache dtype | B33: kv_dtype | C33: ='Config and Summary'!C27 -> fp8
A34: Attention Projections Numeric | B34: attn_proj_dtype | C34: ='Config and Summary'!C28 -> w8a8
A35: Attention Output Projection Numerics | B35: attn_oproj_dtype | C35: ='Config and Summary'!C29 -> w8a8
A36: Attention "K" numeric from KV | B36: attn_kv_k_dtype | C36: ='Config and Summary'!C30 -> bf16
A37: Attention "A" numeric from AV | B37: attn_av_a_dtype | C37: ='Config and Summary'!C31 -> bf16
A38: Expert Dispatch Numeric | B38: expert_dispatch_dtype | C38: ='Config and Summary'!C32 -> fp8
A39: MoE Numeric | B39: moe_dtype | C39: ='Config and Summary'!C33 -> w8a8
A40: Expert Collect Numeric | B40: expert_collect_dtype | C40: ='Config and Summary'!C34 -> bf16
...

Sheet Prefill
A1: Contact: donghyun@, gpolovets@, miliu@. Feedback/Bug reports are welcome!
A2: Description | B2: Symbol | C2: Value | F2: Sharding (Axis Name) | G2: # of Devices | H2: Notes | Q2: Size In Bytes | T2: MXU dtype
A3: Embedding Dimension | B3: D | C3: 7168 | F3: [ ↓ Configurable Values] | Q3: fp4 | R3: 0.5 | T3: =U3&","&V3 -> fp4,fp4 | U3: fp4 | V3: fp4 | W3: fp4
A4: Expert Hidden Dimension | B4: F | C4: 4096 | F4: model | G4: ='Config and Summary'!$D8 -> 1 | Q4: fp8 | R4: 1 | T4: =U4&","&V4 -> fp4,fp8 | U4: fp4 | V4: fp8 | W4: fp8
A5: # of experts | B5: E | C5: 128 | F5: data | G5: ='Config and Summary'!$D9 -> 8 | H5: Also used for expert sharding for MoE | Q5: bf16 | R5: 2 | T5: =U5&","&V5 -> fp4,bf16 | U5: fp4 | V5: bf16 | W5: bf16
A6: # of Layers | B6: L | C6: 61 | F6: seq | G6: ='Config and Summary'!$D10 -> 1 | T6: =U6&","&V6 -> fp8,fp4 | U6: fp8 | V6: fp4 | W6: fp8
A7: # of Dense Layers | B7: DL | C7: 3 | F7: attn_model | G7: ='Config and Summary'!$D11 -> 1 | H7: Used if attention is replicated | T7: =U7&","&V7 -> fp8,fp8 | U7: fp8 | V7: fp8 | W7: fp8
A8: # of experts to be activated per token | B8: top_k | C8: 4 | F8: [ ↓ Derived Values]
A9: The dimension of the compressed latent vector for Query | B9: c_q | C9: 1536 | F9: data,model | G9: =G5*G4 -> 8 | T9: =U9&","&V9 -> fp8,bf16 | U9: fp8 | V9: bf16 | W9: bf16
A10: The dimension of the compressed latent vector for KV | B10: c_kv | C10: 512 | F10: Total # of devices | G10: =PRODUCT(G3:G6) -> 8 | T10: =U10&","&V10 -> bf16,fp4 | U10: bf16 | V10: fp4 | W10: bf16
A11: The dimension of Non-RoPE part of the query head | B11: h_nope | C11: 128 | F11: Total # of chips | G11: =$G$10/$H$18 -> 8 | T11: =U11&","&V11 -> bf16,fp8 | U11: bf16 | V11: fp8 | W11: bf16
A12: The dimension of the RoPE part of the query head | B12: h_rope | C12: 64 | T12: bf16,bf16 | U12: bf16 | V12: bf16 | W12: bf16
A13: The number of Attention Heads (Query) | B13: n_q | C13: 128
A14: [ ↓ Derived parameters]
A15: h_nope+h_rope | B15: h_nope+h_rope | C15: =$C$11+$C$12 -> 192
A16: c_kv+h_rope | B16: c_kv+h_rope | C16: =$C$10+$C$12 -> 576
A17: # of Duplicated tokens (top_k times) | B17: kT | C17: =C8*$C$25 -> 8192 | F17: Hardware Spec | H17: ='Config and Summary'!D4 -> GB200 Derated
A18: # of Devices | B18: num_devices | C18: =$G$10 -> 8 | F18: {=DB!A2:A16} -> # of TensorCore per Chip | H18: {=xlookup($H$17,DB!1:1,DB!2:16)} -> 1
A19: # of Chips | B19: num_chips | C19: =$G$11 -> 8 | F19: Per-Chip HBM-BW (GB/s) | H19: 7200
A20: [TPU] Assumed Topology | B20: topo | C20: =vlookup(C19, DB!$A$26:$F$31, 5, False) -> 2x2x2 | F20: Per-Chip TFLOPS (fp4) | H20: 7500
A21: [TPU] Total # of Bidir Links | B21: num_links_in_topo | C21: =vlookup(C19, DB!$A$26:$F$31, 6, False) -> 12 | F21: Per-Chip TFLOPS (fp8) | H21: 3750
F22: Per-Chip TFLOPS (fp16) | H22: 1875
A23: [ ↓ Configurable parameters] | F23: Per-Chip HBM Capacity (GiB) | H23: 179
A24: Regime | B24: R | C24: Prefill | F24: Per-Core HBM-BW (GB/s) | H24: 7200
A25: Sequence Length (Q) | B25: T | C25: ='Config and Summary'!D14 -> 2048 | F25: Per-Core TFLOPS (fp4) | H25: 7500
A26: Batch Size (power of 2) | B26: B | C26: ='Config and Summary'!D15 -> 8 | F26: Per-Core TFLOPS (fp8) | H26: 3750
A27: Sequence Length (KV) | B27: S | C27: ='Config and Summary'!D16 -> 2048 | F27: Per-Core TFLOPS (bf16) | H27: 1875
A28: Scheduler Latency Overhead | C28: ='Config and Summary'!D18 -> 0 | F28: Per-Core HBM Capacity (GiB) | H28: 179
A29: Roofline Discount Rate | C29: ='Config and Summary'!D19 -> 1 | F29: Core-to-Core ICI Bandwidth (uni, GB/s) | H29: 900
A30: Flash Attention Enabled | B30: flash_attn | C30: ='Config and Summary'!D20 -> TRUE | F30: Chip-to-Chip ICI Bandwidth (uni, GB/s) | H30: 900
A31: Enforce Perfect Expert Routing | B31: enforce_perfect_expert_routing | C31: ='Config and Summary'!D21 -> TRUE | F31: Chip-to-Chip ICI Latency (ms) | H31: 0
A32: [ ↓ Configurable Numeric] | F32: Min MXU Contracting Dim | H32: 1
A33: KV Cache dtype | B33: kv_dtype | C33: ='Config and Summary'!D27 -> fp8
A34: Attention Projections Numeric | B34: attn_proj_dtype | C34: ='Config and Summary'!D28 -> w8a8
A35: Attention Output Projection Numerics | B35: attn_oproj_dtype | C35: ='Config and Summary'!D29 -> w8a8
A36: Attention "K" numeric from KV | B36: attn_kv_k_dtype | C36: ='Config and Summary'!D30 -> bf16
A37: Attention "A" numeric from AV | B37: attn_av_a_dtype | C37: ='Config and Summary'!D31 -> bf16
A38: Expert Dispatch Numeric | B38: expert_dispatch_dtype | C38: ='Config and Summary'!D32 -> fp8
A39: MoE Numeric | B39: moe_dtype | C39: ='Config and Summary'!D33 -> w8a8
A40: Expert Collect Numeric | B40: expert_collect_dtype | C40: ='Config and Summary'!D34 -> bf16
...

Sheet moved to gomistral-ironwood-wor
A1: Description | B1: Date | C1: bs | D1: server | E1: note | F1: metric output at 128 concurrency | H1: log | I1: tok/s/chip | J1: Mean ITL (ms): | K1: prefill time (ms) | L1: decode time (ms) | M1: bucket | N1: decode only xprof | O1: prefill only xprof | P1: plot
A2: fp AG, compiliation sizeTP | D2: --model /mnt/data/hf/hub/models--mistralai--Mistral-Large-3-675B-Instruct-2512/snapshots/5bb3d32a0a147594527f38cb136a8390eaa82222 --max-model-len 32768 --max-num-batched-tokens 2048 --max-num-seqs 8 --no-enable-prefix-caching --tensor-parallel-size 16 --kv-cache-dtype "fp8" --no-async-scheduling --gpu-memory-utilization 0.90 --additional_config='{"compilation_sizes": [128], "sharding": {"sharding_strategy": {"enable_dp_attention": true}}}' --trust-remote-code --port 8000 2>&1 | tee /workspace/tpu_inference/server_run.log | M2: 2026_05_29_05_42_08/ | N2: http://xprof.corp.google.com/trace_viewer/amandaliang-15542864136305965940 | O2: http://xprof.corp.google.com/trace_viewer/amandaliang-2433963231091211163
A3: fp AG, compiliation sizeTPTPcap w2 block size | F3: Successful requests: 1024 Failed requests: 0 Maximum request concurrency: 128 Benchmark duration (s): 332.34 Total input tokens: 2097154 Total generated tokens: 524288 Request throughput (req/s): 3.08 Output token throughput (tok/s): 1577.54 Peak output token throughput (tok/s): 2816.00 Peak concurrent requests: 160.00 Total token throughput (tok/s): 7887.72 ---------------Time to First Token---------------- Mean TTFT (ms): 4457.28 Median TTFT (ms): 3890.57 P99 TTFT (ms): 11773.39 -----Time per Output Token (excl. 1st token)------ Mean TPOT (ms): 68.72 Median TPOT (ms): 67.07 P99 TPOT (ms): 76.58 ---------------Inter-token Latency---------------- Mean ITL (ms): 68.72 Median ITL (ms): 47.20 P99 ITL (ms): 1289.25 ================================================== | I3: =1577.54/8 -> 197.1925 | J3: 68.72 | M3: 2026_05_30_23_07_12/ | N3: http://xprof.corp.google.com/trace_viewer/amandaliang-10442911076544866585 | O3: http://xprof.corp.google.com/trace_viewer/amandaliang-2010731920219961902
A4: =A3 & "fp8 QAG" -> fp AG, compiliation sizeTPTPcap w2 block sizefp8 QAG | M4: 2026_05_31_18_26_41/ | N4: http://xprof.corp.google.com/trace_viewer/amandaliang-10769352853172664673 | O4: http://xprof.corp.google.com/trace_viewer/amandaliang-13858822037780685389
A5: =A4 & " force sc gather" -> fp AG, compiliation sizeTPTPcap w2 block sizefp8 QAG force sc gather | E5: indeed it is slower than dense gather & reduce | M5: 2026_05_31_23_31_44/ | N5: https://xprof.corp.google.com/trace_viewer/amandaliang-6082202138384786625 | O5: https://xprof.corp.google.com/trace_viewer/amandaliang-17487622945553212185?use_trace_viewer_v2=false&show_hats_survey=true&view_start=2947.278&view_end=3025.829
A6: =A5 & " tiling" -> fp AG, compiliation sizeTPTPcap w2 block sizefp8 QAG force sc gather tiling | F6: Successful requests: 1024 Failed requests: 0 Maximum request concurrency: 128 Benchmark duration (s): 330.29 Total input tokens: 2097154 Total generated tokens: 524288 Request throughput (req/s): 3.10 Output token throughput (tok/s): 1587.35 Peak output token throughput (tok/s): 2688.00 Peak concurrent requests: 144.00 Total token throughput (tok/s): 7936.77 ---------------Time to First Token---------------- Mean TTFT (ms): 4169.59 Median TTFT (ms): 3591.18 P99 TTFT (ms): 10905.41 -----Time per Output Token (excl. 1st token)------ Mean TPOT (ms): 68.77 Median TPOT (ms): 67.21 P99 TPOT (ms): 76.17 ---------------Inter-token Latency---------------- Mean ITL (ms): 68.77 Median ITL (ms): 48.72 P99 ITL (ms): 1195.96 ================================================== | I6: =1587.35/8 -> 198.41875 | J6: 68.77 | K6: 19.7 | L6: 0.613 | M6: 2026_06_02_02_57_54/ | N6: http://xprof.corp.google.com/trace_viewer/amandaliang-6916777519404750625 | O6: http://xprof.corp.google.com/trace_viewer/amandaliang-4757591059961737963
A7: use 2560 as the max model len | F7: Successful requests: 1022 Failed requests: 2 Maximum request concurrency: 128 Benchmark duration (s): 291.06 Total input tokens: 2093056 Total generated tokens: 523264 Request throughput (req/s): 3.51 Output token throughput (tok/s): 1797.77 Peak output token throughput (tok/s): 2816.00 Peak concurrent requests: 160.00 Total token throughput (tok/s): 8988.87 ---------------Time to First Token---------------- Mean TTFT (ms): 3863.75 Median TTFT (ms): 3396.87 P99 TTFT (ms): 12403.74 -----Time per Output Token (excl. 1st token)------ Mean TPOT (ms): 63.46 Median TPOT (ms): 65.00 P99 TPOT (ms): 67.59 ---------------Inter-token Latency---------------- Mean ITL (ms): 63.46 Median ITL (ms): 47.90 P99 ITL (ms): 1130.89 | H7: /mnt/disks/persist/server_run_2026_06_04_19_10_38.log | I7: =1798/8 -> 224.75 | M7: gs://mlperf-exp-europe-w/amandaliang/mistral/max-num-batched-tokens-2048/2026_06_05_02_10_31/ | N7: http://xprof.corp.google.com/trace_viewer/amandaliang-11267132432707450113 | O7: http://xprof.corp.google.com/trace_viewer/amandaliang-14196367305023388449
A8: =A7 & " max-num-batched-tokens=1024" -> use 2560 as the max model len max-num-batched-tokens=1024 | E8: half the bs just l inearly reduces the step time. The bottlenecks is still the same. also B*T=1024, which might not be what we want. we want it to be 2048 | F8: Successful requests: 1021 Failed requests: 3 Maximum request concurrency: 128 Benchmark duration (s): 277.68 Total input tokens: 2091008 Total generated tokens: 522752 Request throughput (req/s): 3.68 Output token throughput (tok/s): 1882.56 Peak output token throughput (tok/s): 2741.00 Peak concurrent requests: 144.00 Total token throughput (tok/s): 9412.81 ---------------Time to First Token---------------- Mean TTFT (ms): 2795.31 Median TTFT (ms): 2347.74 P99 TTFT (ms): 10080.84 -----Time per Output Token (excl. 1st token)------ Mean TPOT (ms): 62.42 Median TPOT (ms): 63.25 P99 TPOT (ms): 64.60 ---------------Inter-token Latency---------------- Mean ITL (ms): 62.42 Median ITL (ms): 48.34 P99 ITL (ms): 594.69 ================================================== | I8: =1856/8 -> 232 | M8: mlperf-exp-europe-w/amandaliang/mistral/max-num-batched-tokens-1024 | N8: https://xprof.corp.google.com/trace_viewer/amandaliang-3352838730305239785?view_start=169.289&view_end=176.499 | O8: https://xprof.corp.google.com/trace_viewer/amandaliang-8867064484723102296?view_start=2860.938&view_end=2891.973
A9: =A7 & " remove max-num-batched-tokens" -> use 2560 as the max model len remove max-num-batched-tokens | E9: remove | F9: Successful requests: 1021 Failed requests: 3 Maximum request concurrency: 128 Benchmark duration (s): 292.46 Total input tokens: 2091008 Total generated tokens: 522752 Request throughput (req/s): 3.49 Output token throughput (tok/s): 1787.40 Peak output token throughput (tok/s): 2756.00 Peak concurrent requests: 160.00 Total token throughput (tok/s): 8937.01 ---------------Time to First Token---------------- Mean TTFT (ms): 3905.99 Median TTFT (ms): 3397.30 P99 TTFT (ms): 12452.03 -----Time per Output Token (excl. 1st token)------ Mean TPOT (ms): 63.74 Median TPOT (ms): 64.98 P99 TPOT (ms): 67.57 ---------------Inter-token Latency---------------- Mean ITL (ms): 63.74 Median ITL (ms): 47.99 P99 ITL (ms): 1131.43 ================================================== | I9: =1787/8 -> 223.375 | N9: https://xprof.corp.google.com/trace_viewer/amandaliang-13750897293792486430?view_start=-291.331&view_end=2234.789 | O9: https://xprof.corp.google.com/trace_viewer/amandaliang-14789691241941704881?view_start=-2095.118&view_end=16097.053
A10: =A7 & " MLA" -> use 2560 as the max model len MLA | F10: Successful requests: 1021 Failed requests: 3 Maximum request concurrency: 128 Benchmark duration (s): 289.31 Total input tokens: 2091008 Total generated tokens: 522752 Request throughput (req/s): 3.53 Output token throughput (tok/s): 1806.88 Peak output token throughput (tok/s): 2729.00 Peak concurrent requests: 160.00 Total token throughput (tok/s): 9034.40 ---------------Time to First Token---------------- Mean TTFT (ms): 3623.96 Median TTFT (ms): 3398.07 P99 TTFT (ms): 10328.11 -----Time per Output Token (excl. 1st token)------ Mean TPOT (ms): 63.74 Median TPOT (ms): 63.60 P99 TPOT (ms): 70.71 ---------------Inter-token Latency---------------- Mean ITL (ms): 63.74 Median ITL (ms): 48.30 P99 ITL (ms): 1131.70 ==================================================D15 | I10: =1806/8 -> 225.75 | N10: https://xprof.corp.google.com/trace_viewer/amandaliang-2093135465846270286?view_start=218.971&view_end=219.064 | O10: https://xprof.corp.google.com/trace_viewer/amandaliang-12497654618983940452?view_start=3533.724&view_end=3540.563
A11: =A10 & " 2nd MLA" -> use 2560 as the max model len MLA 2nd MLA | B11: https://github.com/vllm-project/tpu-inference/commit/5e7ebf1f4488cd7aafa4a21baf82c4aaabaaba06 | N11: http://xprof.corp.google.com/trace_viewer/amandaliang-2903148620948916095 | O11: http://xprof.corp.google.com/trace_viewer/amandaliang-9123546916633042004
B12: 46185 | C12: 1 to 128 | D12: MOE_ALL_GATHER_ACTIVATION_DTYPE=fp8 \ VLLM_TPU_PATCH_MM_EMBEDDINGS=1 \ TPU_MULTIHOST_BACKEND=ray \ JAX_PLATFORMS=\"\" \ GMM_VMEM_LIMIT_FRAC=0.85 \ VLLM_DISABLE_SHARED_EXPERTS_STREAM=0 \ MOE_REQUANTIZE_BLOCK_SIZE=512 \ NEW_MODEL_DESIGN=1 \ MODEL_IMPL_TYPE=vllm \ HF_HOME=\"/mnt/disks/persist/hf\" \ TPU_BACKEND_TYPE=jax \ ONEHOT_MOE_PERMUTE_THRESHOLD=2000 \ ATTN_BUCKETIZED_NUM_REQS=true \ ATTN_CUSTOM_NUM_REQS_BUCKETS=\"2,4,8\" \ vllm serve \ --model /mnt/disks/persist/hf/hub/models--mistralai--Mistral-Large-3-675B-Instruct-2512/snapshots/5bb3d32a0a147594527f38cb136a8390eaa82222 \ --max-model-len 3072 \ --max-num-batched-tokens 2048 \ --max-num-seqs 16 \ --no-enable-prefix-caching \ --tensor-parallel-size 16 \ --kv-cache-dtype \"fp8\" \ --async-scheduling \ --gpu-memory-utilization 0.90 \ --additional-config='\''{\"compilation_sizes\": [128], \"sharding\": {\"sharding_strategy\": {\"enable_dp_attention\": true}}}'\'' \ --trust-remote-code \ --port 8000 \ 2>&1 | tee ${LOG_DIR}/${LOG_FILE} | E12: at 1 to 32, we are slightly better than EP | P12: https://ff420afe7652a30f10779d2acd4f8d7a3093f7d96638fb7f001c110-apidata.googleusercontent.com/download/storage/v1/b/mlperf-exp-europe-w/o/amandaliang%2Fmistral%2F20260612_162805%2Fbenchmark_plot.png?jk=ARss-vZTR7W4-1mL-GrDSwGuzm62q5Qqd3jxiDtXR6aFdg4HwCBvw0YaFpKMMKR-FAc_NDCN4sYZr7OqdNJb_Vr5fSfAuWkajPT5O67DNKoavueyI_tl72618FfbrcBnhgjE0wX60FhhtC93Zig5VV8tsXqw9mGmhXuG5aHVGJtUq9R4lvGS5_OMHMUe1n6O5rlIUB2t9a_Cc2LZ2iSdK6UL9Odk3S8osOHw7NU6gzqoyAGEd7wtfTZxQJ2SVHw7nb_9hIlGjk7VDoUW2bp8asr5X5izh_W7bjEBg_GjRVpv3TXTbAdueFWoarxK5tgRjxLg8Sd7LSwEn9LUSmVUx7d5EHKkBTX9LOgYbvTlXTZZijhIHwhr5BiMntOvH4_4d4bgQEmj5BujrXuQy7e7OmLq2IW0IJ-1obLOGUOLC6tjEEsWFb3QgqXZvrnoCQ6un6O8ScGO9TIXGBsqhNn8jIwt9-bCHd9uRxOL3QnptPK0gsDn26Elri9Juj03Deq20Prjo4xNgtuC5cWIIqUEi-IEzHTE-GnhN2RCacObyQf4_g4k7FYVQ5apLoiVra5QGChD7Ig9qZB1fA_fsaCMDd2CgUTpGtoO6ZAYzym-ImdeFBqM_zIfgm0ZMlry92I2Uzkb_jatMlBUORaLzNSQjFyY0gCz9Uslnzhfse5ooleyd6Bce6nLKQq7uKV1ujQy76tnr_gnpacwP-xp9I-5XbYQw_2bULfCQGyGRwT1FgZWlCZGNUUjs97MmvfDRMpiDelkaVRCKfx51DHfZXFEzHcdjahr_pP8Yx6qCFl_nT6kWeCPkmljiIt43aJYxV8Yy8uhp7eKMjbViLOxWVrW1bquZXExl8HpVn79NTaDOZ6tICr4qhpLs6x4QnsachXdfVGwwiTQqXR3RFqSzqfQTQF9i2JOdo3O0GRe4BgN2e5Y__KfL-GSphb7GQVkKNaEYih6pguw_fmNIt-W5cUXX__fPoIR9__dtbRktplbe3tKeCrCB3BM4BfqBwAjT3K0KAty-ZnNIA79EFmfzo1uUfV4uZ802Cmgl5eQ3km3LDddwjvbsswp3O7AJZSg5BAyibeKSn7iRfO-lsC4qUc4ZvoIM9WZ_musVHtXkt_PBxwJwUIGN2lfZ9sQSMY-RBH9yTrf7OBqhJCbVl-72LzxI7QabtO1OoyvDxmZ3Ouh5K4dEQcRR2HI8RKd2ANBh05TJQrejEoJeE4m5-Fv1Zb8N2Qv2w&isca=1
